[2023-12-11T16:40:36.605+0000] {taskinstance.py:1159} INFO - Dependencies all met for dep_context=non-requeueable deps ti=<TaskInstance: airbyte_mambu_data_processing_airflow_dag.airbyte_trigger_sync_journal_entries manual__2023-12-11T16:40:29.510194+00:00 [queued]>
[2023-12-11T16:40:36.609+0000] {taskinstance.py:1159} INFO - Dependencies all met for dep_context=requeueable deps ti=<TaskInstance: airbyte_mambu_data_processing_airflow_dag.airbyte_trigger_sync_journal_entries manual__2023-12-11T16:40:29.510194+00:00 [queued]>
[2023-12-11T16:40:36.610+0000] {taskinstance.py:1361} INFO - Starting attempt 1 of 1
[2023-12-11T16:40:36.616+0000] {taskinstance.py:1382} INFO - Executing <Task(AirbyteTriggerSyncOperator): airbyte_trigger_sync_journal_entries> on 2023-12-11 16:40:29.510194+00:00
[2023-12-11T16:40:36.623+0000] {standard_task_runner.py:57} INFO - Started process 504 to run task
[2023-12-11T16:40:36.631+0000] {standard_task_runner.py:84} INFO - Running: ['***', 'tasks', 'run', 'airbyte_mambu_data_processing_***_dag', 'airbyte_trigger_sync_journal_entries', 'manual__2023-12-11T16:40:29.510194+00:00', '--job-id', '19', '--raw', '--subdir', 'DAGS_FOLDER/mambu_data_processing.py', '--cfg-path', '/tmp/tmpadmzimd9']
[2023-12-11T16:40:36.641+0000] {standard_task_runner.py:85} INFO - Job 19: Subtask airbyte_trigger_sync_journal_entries
[2023-12-11T16:40:36.678+0000] {task_command.py:416} INFO - Running <TaskInstance: airbyte_mambu_data_processing_airflow_dag.airbyte_trigger_sync_journal_entries manual__2023-12-11T16:40:29.510194+00:00 [running]> on host 7a42d9ce34c3
[2023-12-11T16:40:37.241+0000] {taskinstance.py:1662} INFO - Exporting env vars: AIRFLOW_CTX_DAG_OWNER='***' AIRFLOW_CTX_DAG_ID='airbyte_mambu_data_processing_***_dag' AIRFLOW_CTX_TASK_ID='airbyte_trigger_sync_journal_entries' AIRFLOW_CTX_EXECUTION_DATE='2023-12-11T16:40:29.510194+00:00' AIRFLOW_CTX_TRY_NUMBER='1' AIRFLOW_CTX_DAG_RUN_ID='manual__2023-12-11T16:40:29.510194+00:00'
[2023-12-11T16:40:37.265+0000] {base.py:73} INFO - Using connection ID '***-call-to-airbyte' for task execution.
[2023-12-11T16:40:37.271+0000] {http.py:221} WARNING - HTTPConnectionPool(host='localhost', port=8080): Max retries exceeded with url: /api/v1/connections/sync (Caused by NewConnectionError('<urllib3.connection.HTTPConnection object at 0xffff955389d0>: Failed to establish a new connection: [Errno 111] Connection refused')) Tenacity will retry to execute the operation
[2023-12-11T16:40:37.273+0000] {taskinstance.py:1937} ERROR - Task failed with exception
Traceback (most recent call last):
  File "/home/airflow/.local/lib/python3.11/site-packages/urllib3/connection.py", line 174, in _new_conn
    conn = connection.create_connection(
           ^^^^^^^^^^^^^^^^^^^^^^^^^^^^^
  File "/home/airflow/.local/lib/python3.11/site-packages/urllib3/util/connection.py", line 95, in create_connection
    raise err
  File "/home/airflow/.local/lib/python3.11/site-packages/urllib3/util/connection.py", line 85, in create_connection
    sock.connect(sa)
ConnectionRefusedError: [Errno 111] Connection refused

During handling of the above exception, another exception occurred:

Traceback (most recent call last):
  File "/home/airflow/.local/lib/python3.11/site-packages/urllib3/connectionpool.py", line 715, in urlopen
    httplib_response = self._make_request(
                       ^^^^^^^^^^^^^^^^^^^
  File "/home/airflow/.local/lib/python3.11/site-packages/urllib3/connectionpool.py", line 416, in _make_request
    conn.request(method, url, **httplib_request_kw)
  File "/home/airflow/.local/lib/python3.11/site-packages/urllib3/connection.py", line 244, in request
    super(HTTPConnection, self).request(method, url, body=body, headers=headers)
  File "/usr/local/lib/python3.11/http/client.py", line 1286, in request
    self._send_request(method, url, body, headers, encode_chunked)
  File "/usr/local/lib/python3.11/http/client.py", line 1332, in _send_request
    self.endheaders(body, encode_chunked=encode_chunked)
  File "/usr/local/lib/python3.11/http/client.py", line 1281, in endheaders
    self._send_output(message_body, encode_chunked=encode_chunked)
  File "/usr/local/lib/python3.11/http/client.py", line 1041, in _send_output
    self.send(msg)
  File "/usr/local/lib/python3.11/http/client.py", line 979, in send
    self.connect()
  File "/home/airflow/.local/lib/python3.11/site-packages/urllib3/connection.py", line 205, in connect
    conn = self._new_conn()
           ^^^^^^^^^^^^^^^^
  File "/home/airflow/.local/lib/python3.11/site-packages/urllib3/connection.py", line 186, in _new_conn
    raise NewConnectionError(
urllib3.exceptions.NewConnectionError: <urllib3.connection.HTTPConnection object at 0xffff955389d0>: Failed to establish a new connection: [Errno 111] Connection refused

During handling of the above exception, another exception occurred:

Traceback (most recent call last):
  File "/home/airflow/.local/lib/python3.11/site-packages/requests/adapters.py", line 486, in send
    resp = conn.urlopen(
           ^^^^^^^^^^^^^
  File "/home/airflow/.local/lib/python3.11/site-packages/urllib3/connectionpool.py", line 799, in urlopen
    retries = retries.increment(
              ^^^^^^^^^^^^^^^^^^
  File "/home/airflow/.local/lib/python3.11/site-packages/urllib3/util/retry.py", line 592, in increment
    raise MaxRetryError(_pool, url, error or ResponseError(cause))
urllib3.exceptions.MaxRetryError: HTTPConnectionPool(host='localhost', port=8080): Max retries exceeded with url: /api/v1/connections/sync (Caused by NewConnectionError('<urllib3.connection.HTTPConnection object at 0xffff955389d0>: Failed to establish a new connection: [Errno 111] Connection refused'))

During handling of the above exception, another exception occurred:

Traceback (most recent call last):
  File "/home/airflow/.local/lib/python3.11/site-packages/airflow/providers/airbyte/operators/airbyte.py", line 73, in execute
    job_object = self.hook.submit_sync_connection(connection_id=self.connection_id)
                 ^^^^^^^^^^^^^^^^^^^^^^^^^^^^^^^^^^^^^^^^^^^^^^^^^^^^^^^^^^^^^^^^^^
  File "/home/airflow/.local/lib/python3.11/site-packages/airflow/providers/airbyte/hooks/airbyte.py", line 92, in submit_sync_connection
    return self.run(
           ^^^^^^^^^
  File "/home/airflow/.local/lib/python3.11/site-packages/airflow/providers/http/hooks/http.py", line 166, in run
    return self.run_and_check(session, prepped_request, extra_options)
           ^^^^^^^^^^^^^^^^^^^^^^^^^^^^^^^^^^^^^^^^^^^^^^^^^^^^^^^^^^^
  File "/home/airflow/.local/lib/python3.11/site-packages/airflow/providers/http/hooks/http.py", line 222, in run_and_check
    raise ex
  File "/home/airflow/.local/lib/python3.11/site-packages/airflow/providers/http/hooks/http.py", line 214, in run_and_check
    response = session.send(prepped_request, **send_kwargs)
               ^^^^^^^^^^^^^^^^^^^^^^^^^^^^^^^^^^^^^^^^^^^^
  File "/home/airflow/.local/lib/python3.11/site-packages/requests/sessions.py", line 703, in send
    r = adapter.send(request, **kwargs)
        ^^^^^^^^^^^^^^^^^^^^^^^^^^^^^^^
  File "/home/airflow/.local/lib/python3.11/site-packages/requests/adapters.py", line 519, in send
    raise ConnectionError(e, request=request)
requests.exceptions.ConnectionError: HTTPConnectionPool(host='localhost', port=8080): Max retries exceeded with url: /api/v1/connections/sync (Caused by NewConnectionError('<urllib3.connection.HTTPConnection object at 0xffff955389d0>: Failed to establish a new connection: [Errno 111] Connection refused'))
[2023-12-11T16:40:37.302+0000] {taskinstance.py:1400} INFO - Marking task as FAILED. dag_id=airbyte_mambu_data_processing_***_dag, task_id=airbyte_trigger_sync_journal_entries, execution_date=20231211T164029, start_date=20231211T164036, end_date=20231211T164037
[2023-12-11T16:40:37.314+0000] {standard_task_runner.py:104} ERROR - Failed to execute job 19 for task airbyte_trigger_sync_journal_entries (HTTPConnectionPool(host='localhost', port=8080): Max retries exceeded with url: /api/v1/connections/sync (Caused by NewConnectionError('<urllib3.connection.HTTPConnection object at 0xffff955389d0>: Failed to establish a new connection: [Errno 111] Connection refused')); 504)
[2023-12-11T16:40:37.349+0000] {local_task_job_runner.py:228} INFO - Task exited with return code 1
[2023-12-11T16:40:37.365+0000] {taskinstance.py:2778} INFO - 0 downstream tasks scheduled from follow-on schedule check
