[2023-11-27T12:39:29.707+0000] {taskinstance.py:1159} INFO - Dependencies all met for dep_context=non-requeueable deps ti=<TaskInstance: airbyte_example_airflow_dag.airbyte_check_sync manual__2023-11-27T12:39:24.424446+00:00 [queued]>
[2023-11-27T12:39:29.751+0000] {taskinstance.py:1159} INFO - Dependencies all met for dep_context=requeueable deps ti=<TaskInstance: airbyte_example_airflow_dag.airbyte_check_sync manual__2023-11-27T12:39:24.424446+00:00 [queued]>
[2023-11-27T12:39:29.751+0000] {taskinstance.py:1361} INFO - Starting attempt 1 of 1
[2023-11-27T12:39:29.859+0000] {taskinstance.py:1382} INFO - Executing <Task(AirbyteJobSensor): airbyte_check_sync> on 2023-11-27 12:39:24.424446+00:00
[2023-11-27T12:39:29.870+0000] {standard_task_runner.py:57} INFO - Started process 2699 to run task
[2023-11-27T12:39:29.875+0000] {standard_task_runner.py:84} INFO - Running: ['***', 'tasks', 'run', 'airbyte_example_***_dag', 'airbyte_check_sync', 'manual__2023-11-27T12:39:24.424446+00:00', '--job-id', '111', '--raw', '--subdir', 'DAGS_FOLDER/example.py', '--cfg-path', '/tmp/tmpbg116vn9']
[2023-11-27T12:39:29.878+0000] {standard_task_runner.py:85} INFO - Job 111: Subtask airbyte_check_sync
[2023-11-27T12:39:30.043+0000] {task_command.py:416} INFO - Running <TaskInstance: airbyte_example_airflow_dag.airbyte_check_sync manual__2023-11-27T12:39:24.424446+00:00 [running]> on host 471f0a6f2fee
[2023-11-27T12:39:30.231+0000] {taskinstance.py:1662} INFO - Exporting env vars: AIRFLOW_CTX_DAG_OWNER='***' AIRFLOW_CTX_DAG_ID='airbyte_example_***_dag' AIRFLOW_CTX_TASK_ID='airbyte_check_sync' AIRFLOW_CTX_EXECUTION_DATE='2023-11-27T12:39:24.424446+00:00' AIRFLOW_CTX_TRY_NUMBER='1' AIRFLOW_CTX_DAG_RUN_ID='manual__2023-11-27T12:39:24.424446+00:00'
[2023-11-27T12:39:30.245+0000] {base.py:73} INFO - Using connection ID '***-call-to-airbyte-example' for task execution.
[2023-11-27T12:39:30.257+0000] {airbyte.py:80} INFO - Waiting for job 61 to complete.
[2023-11-27T12:40:00.392+0000] {local_task_job_runner.py:294} WARNING - State of this instance has been externally set to failed. Terminating instance.
[2023-11-27T12:40:00.393+0000] {process_utils.py:131} INFO - Sending 15 to group 2699. PIDs of all processes in the group: [2699]
[2023-11-27T12:40:00.394+0000] {process_utils.py:86} INFO - Sending the signal 15 to group 2699
[2023-11-27T12:40:00.394+0000] {taskinstance.py:1632} ERROR - Received SIGTERM. Terminating subprocesses.
[2023-11-27T12:40:00.446+0000] {process_utils.py:79} INFO - Process psutil.Process(pid=2699, status='terminated', exitcode=0, started='12:39:29') (2699) terminated with exit code 0
