[2023-11-27T13:05:16.953+0000] {taskinstance.py:1159} INFO - Dependencies all met for dep_context=non-requeueable deps ti=<TaskInstance: airbyte_example_airflow_dag.airbyte_check_sync manual__2023-11-27T13:05:01.765644+00:00 [queued]>
[2023-11-27T13:05:16.959+0000] {taskinstance.py:1159} INFO - Dependencies all met for dep_context=requeueable deps ti=<TaskInstance: airbyte_example_airflow_dag.airbyte_check_sync manual__2023-11-27T13:05:01.765644+00:00 [queued]>
[2023-11-27T13:05:16.960+0000] {taskinstance.py:1361} INFO - Starting attempt 1 of 1
[2023-11-27T13:05:16.993+0000] {taskinstance.py:1382} INFO - Executing <Task(AirbyteJobSensor): airbyte_check_sync> on 2023-11-27 13:05:01.765644+00:00
[2023-11-27T13:05:16.999+0000] {standard_task_runner.py:57} INFO - Started process 3227 to run task
[2023-11-27T13:05:17.001+0000] {standard_task_runner.py:84} INFO - Running: ['***', 'tasks', 'run', 'airbyte_example_***_dag', 'airbyte_check_sync', 'manual__2023-11-27T13:05:01.765644+00:00', '--job-id', '159', '--raw', '--subdir', 'DAGS_FOLDER/example.py', '--cfg-path', '/tmp/tmpqpznar63']
[2023-11-27T13:05:17.002+0000] {standard_task_runner.py:85} INFO - Job 159: Subtask airbyte_check_sync
[2023-11-27T13:05:17.071+0000] {task_command.py:416} INFO - Running <TaskInstance: airbyte_example_airflow_dag.airbyte_check_sync manual__2023-11-27T13:05:01.765644+00:00 [running]> on host 471f0a6f2fee
[2023-11-27T13:05:17.215+0000] {taskinstance.py:1662} INFO - Exporting env vars: AIRFLOW_CTX_DAG_OWNER='***' AIRFLOW_CTX_DAG_ID='airbyte_example_***_dag' AIRFLOW_CTX_TASK_ID='airbyte_check_sync' AIRFLOW_CTX_EXECUTION_DATE='2023-11-27T13:05:01.765644+00:00' AIRFLOW_CTX_TRY_NUMBER='1' AIRFLOW_CTX_DAG_RUN_ID='manual__2023-11-27T13:05:01.765644+00:00'
[2023-11-27T13:05:17.222+0000] {base.py:73} INFO - Using connection ID '***-call-to-airbyte-example' for task execution.
[2023-11-27T13:05:17.229+0000] {airbyte.py:80} INFO - Waiting for job 74 to complete.
[2023-11-27T13:06:02.979+0000] {local_task_job_runner.py:294} WARNING - State of this instance has been externally set to failed. Terminating instance.
[2023-11-27T13:06:02.980+0000] {process_utils.py:131} INFO - Sending 15 to group 3227. PIDs of all processes in the group: [3227]
[2023-11-27T13:06:02.981+0000] {process_utils.py:86} INFO - Sending the signal 15 to group 3227
[2023-11-27T13:06:02.982+0000] {taskinstance.py:1632} ERROR - Received SIGTERM. Terminating subprocesses.
[2023-11-27T13:06:03.160+0000] {process_utils.py:79} INFO - Process psutil.Process(pid=3227, status='terminated', exitcode=0, started='13:05:16') (3227) terminated with exit code 0
