[2023-11-27T12:53:08.084+0000] {taskinstance.py:1159} INFO - Dependencies all met for dep_context=non-requeueable deps ti=<TaskInstance: airbyte_example_airflow_dag.airbyte_check_sync manual__2023-11-27T12:53:02.151497+00:00 [queued]>
[2023-11-27T12:53:08.097+0000] {taskinstance.py:1159} INFO - Dependencies all met for dep_context=requeueable deps ti=<TaskInstance: airbyte_example_airflow_dag.airbyte_check_sync manual__2023-11-27T12:53:02.151497+00:00 [queued]>
[2023-11-27T12:53:08.098+0000] {taskinstance.py:1361} INFO - Starting attempt 1 of 1
[2023-11-27T12:53:08.145+0000] {taskinstance.py:1382} INFO - Executing <Task(AirbyteJobSensor): airbyte_check_sync> on 2023-11-27 12:53:02.151497+00:00
[2023-11-27T12:53:08.152+0000] {standard_task_runner.py:57} INFO - Started process 2976 to run task
[2023-11-27T12:53:08.155+0000] {standard_task_runner.py:84} INFO - Running: ['***', 'tasks', 'run', 'airbyte_example_***_dag', 'airbyte_check_sync', 'manual__2023-11-27T12:53:02.151497+00:00', '--job-id', '135', '--raw', '--subdir', 'DAGS_FOLDER/example.py', '--cfg-path', '/tmp/tmppuqmg0n9']
[2023-11-27T12:53:08.156+0000] {standard_task_runner.py:85} INFO - Job 135: Subtask airbyte_check_sync
[2023-11-27T12:53:08.247+0000] {task_command.py:416} INFO - Running <TaskInstance: airbyte_example_airflow_dag.airbyte_check_sync manual__2023-11-27T12:53:02.151497+00:00 [running]> on host 471f0a6f2fee
[2023-11-27T12:53:08.538+0000] {taskinstance.py:1662} INFO - Exporting env vars: AIRFLOW_CTX_DAG_OWNER='***' AIRFLOW_CTX_DAG_ID='airbyte_example_***_dag' AIRFLOW_CTX_TASK_ID='airbyte_check_sync' AIRFLOW_CTX_EXECUTION_DATE='2023-11-27T12:53:02.151497+00:00' AIRFLOW_CTX_TRY_NUMBER='1' AIRFLOW_CTX_DAG_RUN_ID='manual__2023-11-27T12:53:02.151497+00:00'
[2023-11-27T12:53:08.558+0000] {base.py:73} INFO - Using connection ID '***-call-to-airbyte-example' for task execution.
[2023-11-27T12:53:08.573+0000] {airbyte.py:80} INFO - Waiting for job 68 to complete.
[2023-11-27T12:53:23.411+0000] {local_task_job_runner.py:294} WARNING - State of this instance has been externally set to failed. Terminating instance.
[2023-11-27T12:53:23.413+0000] {process_utils.py:131} INFO - Sending 15 to group 2976. PIDs of all processes in the group: [2976]
[2023-11-27T12:53:23.414+0000] {process_utils.py:86} INFO - Sending the signal 15 to group 2976
[2023-11-27T12:53:23.414+0000] {taskinstance.py:1632} ERROR - Received SIGTERM. Terminating subprocesses.
[2023-11-27T12:53:23.506+0000] {process_utils.py:79} INFO - Process psutil.Process(pid=2976, status='terminated', exitcode=0, started='12:53:07') (2976) terminated with exit code 0
