[2023-12-05T15:02:54.912+0000] {taskinstance.py:1159} INFO - Dependencies all met for dep_context=non-requeueable deps ti=<TaskInstance: airbyte_example_airflow_dag.airbyte_trigger_sync manual__2023-12-05T15:02:53.134688+00:00 [queued]>
[2023-12-05T15:02:54.919+0000] {taskinstance.py:1159} INFO - Dependencies all met for dep_context=requeueable deps ti=<TaskInstance: airbyte_example_airflow_dag.airbyte_trigger_sync manual__2023-12-05T15:02:53.134688+00:00 [queued]>
[2023-12-05T15:02:54.919+0000] {taskinstance.py:1361} INFO - Starting attempt 1 of 1
[2023-12-05T15:02:54.952+0000] {taskinstance.py:1382} INFO - Executing <Task(AirbyteTriggerSyncOperator): airbyte_trigger_sync> on 2023-12-05 15:02:53.134688+00:00
[2023-12-05T15:02:54.959+0000] {standard_task_runner.py:57} INFO - Started process 116 to run task
[2023-12-05T15:02:54.961+0000] {standard_task_runner.py:84} INFO - Running: ['***', 'tasks', 'run', 'airbyte_example_***_dag', 'airbyte_trigger_sync', 'manual__2023-12-05T15:02:53.134688+00:00', '--job-id', '227', '--raw', '--subdir', 'DAGS_FOLDER/example.py', '--cfg-path', '/tmp/tmppakfsotk']
[2023-12-05T15:02:54.962+0000] {standard_task_runner.py:85} INFO - Job 227: Subtask airbyte_trigger_sync
[2023-12-05T15:02:55.031+0000] {task_command.py:416} INFO - Running <TaskInstance: airbyte_example_airflow_dag.airbyte_trigger_sync manual__2023-12-05T15:02:53.134688+00:00 [running]> on host 650bf87b91c7
[2023-12-05T15:02:55.346+0000] {taskinstance.py:1662} INFO - Exporting env vars: AIRFLOW_CTX_DAG_OWNER='***' AIRFLOW_CTX_DAG_ID='airbyte_example_***_dag' AIRFLOW_CTX_TASK_ID='airbyte_trigger_sync' AIRFLOW_CTX_EXECUTION_DATE='2023-12-05T15:02:53.134688+00:00' AIRFLOW_CTX_TRY_NUMBER='1' AIRFLOW_CTX_DAG_RUN_ID='manual__2023-12-05T15:02:53.134688+00:00'
[2023-12-05T15:02:55.360+0000] {base.py:73} INFO - Using connection ID '***-call-to-airbyte-example' for task execution.
[2023-12-05T15:02:55.367+0000] {http.py:221} WARNING - ('Connection aborted.', ConnectionResetError(104, 'Connection reset by peer')) Tenacity will retry to execute the operation
[2023-12-05T15:02:55.367+0000] {taskinstance.py:1937} ERROR - Task failed with exception
Traceback (most recent call last):
  File "/home/airflow/.local/lib/python3.8/site-packages/urllib3/connectionpool.py", line 715, in urlopen
    httplib_response = self._make_request(
  File "/home/airflow/.local/lib/python3.8/site-packages/urllib3/connectionpool.py", line 467, in _make_request
    six.raise_from(e, None)
  File "<string>", line 3, in raise_from
  File "/home/airflow/.local/lib/python3.8/site-packages/urllib3/connectionpool.py", line 462, in _make_request
    httplib_response = conn.getresponse()
  File "/usr/local/lib/python3.8/http/client.py", line 1348, in getresponse
    response.begin()
  File "/usr/local/lib/python3.8/http/client.py", line 316, in begin
    version, status, reason = self._read_status()
  File "/usr/local/lib/python3.8/http/client.py", line 277, in _read_status
    line = str(self.fp.readline(_MAXLINE + 1), "iso-8859-1")
  File "/usr/local/lib/python3.8/socket.py", line 669, in readinto
    return self._sock.recv_into(b)
ConnectionResetError: [Errno 104] Connection reset by peer

During handling of the above exception, another exception occurred:

Traceback (most recent call last):
  File "/home/airflow/.local/lib/python3.8/site-packages/requests/adapters.py", line 486, in send
    resp = conn.urlopen(
  File "/home/airflow/.local/lib/python3.8/site-packages/urllib3/connectionpool.py", line 799, in urlopen
    retries = retries.increment(
  File "/home/airflow/.local/lib/python3.8/site-packages/urllib3/util/retry.py", line 550, in increment
    raise six.reraise(type(error), error, _stacktrace)
  File "/home/airflow/.local/lib/python3.8/site-packages/urllib3/packages/six.py", line 769, in reraise
    raise value.with_traceback(tb)
  File "/home/airflow/.local/lib/python3.8/site-packages/urllib3/connectionpool.py", line 715, in urlopen
    httplib_response = self._make_request(
  File "/home/airflow/.local/lib/python3.8/site-packages/urllib3/connectionpool.py", line 467, in _make_request
    six.raise_from(e, None)
  File "<string>", line 3, in raise_from
  File "/home/airflow/.local/lib/python3.8/site-packages/urllib3/connectionpool.py", line 462, in _make_request
    httplib_response = conn.getresponse()
  File "/usr/local/lib/python3.8/http/client.py", line 1348, in getresponse
    response.begin()
  File "/usr/local/lib/python3.8/http/client.py", line 316, in begin
    version, status, reason = self._read_status()
  File "/usr/local/lib/python3.8/http/client.py", line 277, in _read_status
    line = str(self.fp.readline(_MAXLINE + 1), "iso-8859-1")
  File "/usr/local/lib/python3.8/socket.py", line 669, in readinto
    return self._sock.recv_into(b)
urllib3.exceptions.ProtocolError: ('Connection aborted.', ConnectionResetError(104, 'Connection reset by peer'))

During handling of the above exception, another exception occurred:

Traceback (most recent call last):
  File "/home/airflow/.local/lib/python3.8/site-packages/airflow/providers/airbyte/operators/airbyte.py", line 73, in execute
    job_object = self.hook.submit_sync_connection(connection_id=self.connection_id)
  File "/home/airflow/.local/lib/python3.8/site-packages/airflow/providers/airbyte/hooks/airbyte.py", line 92, in submit_sync_connection
    return self.run(
  File "/home/airflow/.local/lib/python3.8/site-packages/airflow/providers/http/hooks/http.py", line 166, in run
    return self.run_and_check(session, prepped_request, extra_options)
  File "/home/airflow/.local/lib/python3.8/site-packages/airflow/providers/http/hooks/http.py", line 222, in run_and_check
    raise ex
  File "/home/airflow/.local/lib/python3.8/site-packages/airflow/providers/http/hooks/http.py", line 214, in run_and_check
    response = session.send(prepped_request, **send_kwargs)
  File "/home/airflow/.local/lib/python3.8/site-packages/requests/sessions.py", line 703, in send
    r = adapter.send(request, **kwargs)
  File "/home/airflow/.local/lib/python3.8/site-packages/requests/adapters.py", line 501, in send
    raise ConnectionError(err, request=request)
requests.exceptions.ConnectionError: ('Connection aborted.', ConnectionResetError(104, 'Connection reset by peer'))
[2023-12-05T15:02:55.378+0000] {taskinstance.py:1400} INFO - Marking task as FAILED. dag_id=airbyte_example_***_dag, task_id=airbyte_trigger_sync, execution_date=20231205T150253, start_date=20231205T150254, end_date=20231205T150255
[2023-12-05T15:02:55.420+0000] {standard_task_runner.py:104} ERROR - Failed to execute job 227 for task airbyte_trigger_sync (('Connection aborted.', ConnectionResetError(104, 'Connection reset by peer')); 116)
[2023-12-05T15:02:55.454+0000] {local_task_job_runner.py:228} INFO - Task exited with return code 1
[2023-12-05T15:02:55.481+0000] {taskinstance.py:2778} INFO - 0 downstream tasks scheduled from follow-on schedule check
