[2023-11-23T03:00:37.620+0000] {taskinstance.py:1159} INFO - Dependencies all met for dep_context=non-requeueable deps ti=<TaskInstance: airbyte_example_airflow_dag.airbyte_trigger_sync manual__2023-11-23T03:00:36.543755+00:00 [queued]>
[2023-11-23T03:00:37.626+0000] {taskinstance.py:1159} INFO - Dependencies all met for dep_context=requeueable deps ti=<TaskInstance: airbyte_example_airflow_dag.airbyte_trigger_sync manual__2023-11-23T03:00:36.543755+00:00 [queued]>
[2023-11-23T03:00:37.627+0000] {taskinstance.py:1361} INFO - Starting attempt 1 of 1
[2023-11-23T03:00:37.662+0000] {taskinstance.py:1382} INFO - Executing <Task(AirbyteTriggerSyncOperator): airbyte_trigger_sync> on 2023-11-23 03:00:36.543755+00:00
[2023-11-23T03:00:37.667+0000] {standard_task_runner.py:57} INFO - Started process 116 to run task
[2023-11-23T03:00:37.669+0000] {standard_task_runner.py:84} INFO - Running: ['***', 'tasks', 'run', 'airbyte_example_***_dag', 'airbyte_trigger_sync', 'manual__2023-11-23T03:00:36.543755+00:00', '--job-id', '47', '--raw', '--subdir', 'DAGS_FOLDER/example.py', '--cfg-path', '/tmp/tmpjpveurjv']
[2023-11-23T03:00:37.670+0000] {standard_task_runner.py:85} INFO - Job 47: Subtask airbyte_trigger_sync
[2023-11-23T03:00:37.735+0000] {task_command.py:416} INFO - Running <TaskInstance: airbyte_example_airflow_dag.airbyte_trigger_sync manual__2023-11-23T03:00:36.543755+00:00 [running]> on host 471f0a6f2fee
[2023-11-23T03:00:37.868+0000] {taskinstance.py:1662} INFO - Exporting env vars: AIRFLOW_CTX_DAG_OWNER='***' AIRFLOW_CTX_DAG_ID='airbyte_example_***_dag' AIRFLOW_CTX_TASK_ID='airbyte_trigger_sync' AIRFLOW_CTX_EXECUTION_DATE='2023-11-23T03:00:36.543755+00:00' AIRFLOW_CTX_TRY_NUMBER='1' AIRFLOW_CTX_DAG_RUN_ID='manual__2023-11-23T03:00:36.543755+00:00'
[2023-11-23T03:00:37.874+0000] {base.py:73} INFO - Using connection ID '***-call-to-airbyte-example' for task execution.
[2023-11-23T03:00:37.881+0000] {http.py:178} ERROR - HTTP error: Bad Request
[2023-11-23T03:00:37.881+0000] {http.py:179} ERROR - {"message":"Bad Request","_links":{"self":{"href":"/api/v1/connections/sync","templated":false}},"_embedded":{"errors":[{"message":"Failed to convert argument [connectionIdRequestBody] for value [null] due to: Cannot deserialize value of type `java.util.UUID` from String \"[REPLACE THIS WITH YOUR CONNECTION ID]\": UUID has to be represented by standard 36-char representation\n at [Source: UNKNOWN; byte offset: #UNKNOWN] (through reference chain: io.airbyte.api.model.generated.ConnectionIdRequestBody[\"connectionId\"])","path":"/connectionIdRequestBody"}]}}
[2023-11-23T03:00:37.889+0000] {taskinstance.py:1937} ERROR - Task failed with exception
Traceback (most recent call last):
  File "/home/airflow/.local/lib/python3.8/site-packages/airflow/providers/http/hooks/http.py", line 176, in check_response
    response.raise_for_status()
  File "/home/airflow/.local/lib/python3.8/site-packages/requests/models.py", line 1021, in raise_for_status
    raise HTTPError(http_error_msg, response=self)
requests.exceptions.HTTPError: 400 Client Error: Bad Request for url: http://host.docker.internal:8000/api/v1/connections/sync

During handling of the above exception, another exception occurred:

Traceback (most recent call last):
  File "/home/airflow/.local/lib/python3.8/site-packages/airflow/providers/airbyte/operators/airbyte.py", line 73, in execute
    job_object = self.hook.submit_sync_connection(connection_id=self.connection_id)
  File "/home/airflow/.local/lib/python3.8/site-packages/airflow/providers/airbyte/hooks/airbyte.py", line 92, in submit_sync_connection
    return self.run(
  File "/home/airflow/.local/lib/python3.8/site-packages/airflow/providers/http/hooks/http.py", line 166, in run
    return self.run_and_check(session, prepped_request, extra_options)
  File "/home/airflow/.local/lib/python3.8/site-packages/airflow/providers/http/hooks/http.py", line 217, in run_and_check
    self.check_response(response)
  File "/home/airflow/.local/lib/python3.8/site-packages/airflow/providers/http/hooks/http.py", line 180, in check_response
    raise AirflowException(str(response.status_code) + ":" + response.reason)
airflow.exceptions.AirflowException: 400:Bad Request
[2023-11-23T03:00:37.891+0000] {taskinstance.py:1400} INFO - Marking task as FAILED. dag_id=airbyte_example_***_dag, task_id=airbyte_trigger_sync, execution_date=20231123T030036, start_date=20231123T030037, end_date=20231123T030037
[2023-11-23T03:00:37.933+0000] {standard_task_runner.py:104} ERROR - Failed to execute job 47 for task airbyte_trigger_sync (400:Bad Request; 116)
[2023-11-23T03:00:37.961+0000] {local_task_job_runner.py:228} INFO - Task exited with return code 1
[2023-11-23T03:00:37.980+0000] {taskinstance.py:2778} INFO - 0 downstream tasks scheduled from follow-on schedule check
