[2023-12-12T02:18:08.110+0000] {taskinstance.py:1159} INFO - Dependencies all met for dep_context=non-requeueable deps ti=<TaskInstance: airbyte_rtgs_data_processing_airflow_dag.save_rtgs_data_to_local_file manual__2023-12-12T02:14:29.582394+00:00 [queued]>
[2023-12-12T02:18:08.114+0000] {taskinstance.py:1159} INFO - Dependencies all met for dep_context=requeueable deps ti=<TaskInstance: airbyte_rtgs_data_processing_airflow_dag.save_rtgs_data_to_local_file manual__2023-12-12T02:14:29.582394+00:00 [queued]>
[2023-12-12T02:18:08.114+0000] {taskinstance.py:1361} INFO - Starting attempt 1 of 1
[2023-12-12T02:18:08.120+0000] {taskinstance.py:1382} INFO - Executing <Task(PythonOperator): save_rtgs_data_to_local_file> on 2023-12-12 02:14:29.582394+00:00
[2023-12-12T02:18:08.125+0000] {standard_task_runner.py:57} INFO - Started process 665 to run task
[2023-12-12T02:18:08.127+0000] {standard_task_runner.py:84} INFO - Running: ['***', 'tasks', 'run', 'airbyte_rtgs_data_processing_***_dag', 'save_rtgs_data_to_local_file', 'manual__2023-12-12T02:14:29.582394+00:00', '--job-id', '112', '--raw', '--subdir', 'DAGS_FOLDER/rtgs_data_processing.py', '--cfg-path', '/tmp/tmppcnzjvof']
[2023-12-12T02:18:08.130+0000] {standard_task_runner.py:85} INFO - Job 112: Subtask save_rtgs_data_to_local_file
[2023-12-12T02:18:08.153+0000] {task_command.py:416} INFO - Running <TaskInstance: airbyte_rtgs_data_processing_airflow_dag.save_rtgs_data_to_local_file manual__2023-12-12T02:14:29.582394+00:00 [running]> on host 86ddea81acd7
[2023-12-12T02:18:08.318+0000] {taskinstance.py:1662} INFO - Exporting env vars: AIRFLOW_CTX_DAG_OWNER='***' AIRFLOW_CTX_DAG_ID='airbyte_rtgs_data_processing_***_dag' AIRFLOW_CTX_TASK_ID='save_rtgs_data_to_local_file' AIRFLOW_CTX_EXECUTION_DATE='2023-12-12T02:14:29.582394+00:00' AIRFLOW_CTX_TRY_NUMBER='1' AIRFLOW_CTX_DAG_RUN_ID='manual__2023-12-12T02:14:29.582394+00:00'
[2023-12-12T02:18:08.322+0000] {taskinstance.py:1937} ERROR - Task failed with exception
Traceback (most recent call last):
  File "/home/airflow/.local/lib/python3.11/site-packages/airflow/operators/python.py", line 192, in execute
    return_value = self.execute_callable()
                   ^^^^^^^^^^^^^^^^^^^^^^^
  File "/home/airflow/.local/lib/python3.11/site-packages/airflow/operators/python.py", line 209, in execute_callable
    return self.python_callable(*self.op_args, **self.op_kwargs)
           ^^^^^^^^^^^^^^^^^^^^^^^^^^^^^^^^^^^^^^^^^^^^^^^^^^^^^
  File "/opt/airflow/dags/rtgs_data_processing.py", line 29, in save_data_to_local_file
    df.to_csv(file_path, sep='|', index=False)
    ^^^^^^^^^
AttributeError: 'NoneType' object has no attribute 'to_csv'
[2023-12-12T02:18:08.326+0000] {taskinstance.py:1400} INFO - Marking task as FAILED. dag_id=airbyte_rtgs_data_processing_***_dag, task_id=save_rtgs_data_to_local_file, execution_date=20231212T021429, start_date=20231212T021808, end_date=20231212T021808
[2023-12-12T02:18:08.331+0000] {standard_task_runner.py:104} ERROR - Failed to execute job 112 for task save_rtgs_data_to_local_file ('NoneType' object has no attribute 'to_csv'; 665)
[2023-12-12T02:18:08.341+0000] {local_task_job_runner.py:228} INFO - Task exited with return code 1
[2023-12-12T02:18:08.350+0000] {taskinstance.py:2778} INFO - 0 downstream tasks scheduled from follow-on schedule check
