[2023-12-12T01:29:38.390+0000] {taskinstance.py:1159} INFO - Dependencies all met for dep_context=non-requeueable deps ti=<TaskInstance: airbyte_rtgs_data_processing_airflow_dag.airbyte_check_deposit_transactions manual__2023-12-12T01:29:17.597683+00:00 [queued]>
[2023-12-12T01:29:38.397+0000] {taskinstance.py:1159} INFO - Dependencies all met for dep_context=requeueable deps ti=<TaskInstance: airbyte_rtgs_data_processing_airflow_dag.airbyte_check_deposit_transactions manual__2023-12-12T01:29:17.597683+00:00 [queued]>
[2023-12-12T01:29:38.399+0000] {taskinstance.py:1361} INFO - Starting attempt 1 of 1
[2023-12-12T01:29:38.451+0000] {taskinstance.py:1382} INFO - Executing <Task(AirbyteJobSensor): airbyte_check_deposit_transactions> on 2023-12-12 01:29:17.597683+00:00
[2023-12-12T01:29:38.467+0000] {standard_task_runner.py:57} INFO - Started process 424 to run task
[2023-12-12T01:29:38.475+0000] {standard_task_runner.py:84} INFO - Running: ['***', 'tasks', 'run', 'airbyte_rtgs_data_processing_***_dag', 'airbyte_check_deposit_transactions', 'manual__2023-12-12T01:29:17.597683+00:00', '--job-id', '72', '--raw', '--subdir', 'DAGS_FOLDER/rtgs_data_processing.py', '--cfg-path', '/tmp/tmpnyp8w7ug']
[2023-12-12T01:29:38.495+0000] {standard_task_runner.py:85} INFO - Job 72: Subtask airbyte_check_deposit_transactions
[2023-12-12T01:29:38.601+0000] {task_command.py:416} INFO - Running <TaskInstance: airbyte_rtgs_data_processing_airflow_dag.airbyte_check_deposit_transactions manual__2023-12-12T01:29:17.597683+00:00 [running]> on host 86ddea81acd7
[2023-12-12T01:29:39.422+0000] {taskinstance.py:1662} INFO - Exporting env vars: AIRFLOW_CTX_DAG_OWNER='***' AIRFLOW_CTX_DAG_ID='airbyte_rtgs_data_processing_***_dag' AIRFLOW_CTX_TASK_ID='airbyte_check_deposit_transactions' AIRFLOW_CTX_EXECUTION_DATE='2023-12-12T01:29:17.597683+00:00' AIRFLOW_CTX_TRY_NUMBER='1' AIRFLOW_CTX_DAG_RUN_ID='manual__2023-12-12T01:29:17.597683+00:00'
[2023-12-12T01:29:39.447+0000] {base.py:73} INFO - Using connection ID '***-call-to-airbyte' for task execution.
[2023-12-12T01:29:39.569+0000] {airbyte.py:80} INFO - Waiting for job 24 to complete.
[2023-12-12T01:30:39.755+0000] {base.py:73} INFO - Using connection ID '***-call-to-airbyte' for task execution.
[2023-12-12T01:30:39.809+0000] {airbyte.py:80} INFO - Waiting for job 24 to complete.
[2023-12-12T01:31:40.732+0000] {base.py:73} INFO - Using connection ID '***-call-to-airbyte' for task execution.
[2023-12-12T01:33:15.213+0000] {http.py:178} ERROR - HTTP error: Bad Gateway
[2023-12-12T01:33:15.308+0000] {http.py:179} ERROR - <!DOCTYPE html>
<html>
<head>
<title>Error</title>
<style>
html { color-scheme: light dark; }
body { width: 35em; margin: 0 auto;
font-family: Tahoma, Verdana, Arial, sans-serif; }
</style>
</head>
<body>
<h1>An error occurred.</h1>
<p>Sorry, the page you are looking for is currently unavailable.<br/>
Please try again later.</p>
<p>If you are the system administrator of this resource then you should check
the error log for details.</p>
<p><em>Faithfully yours, nginx.</em></p>
</body>
</html>

[2023-12-12T01:33:15.777+0000] {taskinstance.py:1937} ERROR - Task failed with exception
Traceback (most recent call last):
  File "/home/airflow/.local/lib/python3.11/site-packages/airflow/providers/http/hooks/http.py", line 176, in check_response
    response.raise_for_status()
  File "/home/airflow/.local/lib/python3.11/site-packages/requests/models.py", line 1021, in raise_for_status
    raise HTTPError(http_error_msg, response=self)
requests.exceptions.HTTPError: 502 Server Error: Bad Gateway for url: http://host.docker.internal:80/api/v1/jobs/get

During handling of the above exception, another exception occurred:

Traceback (most recent call last):
  File "/home/airflow/.local/lib/python3.11/site-packages/airflow/sensors/base.py", line 257, in execute
    raise e
  File "/home/airflow/.local/lib/python3.11/site-packages/airflow/sensors/base.py", line 239, in execute
    poke_return = self.poke(context)
                  ^^^^^^^^^^^^^^^^^^
  File "/home/airflow/.local/lib/python3.11/site-packages/airflow/providers/airbyte/sensors/airbyte.py", line 59, in poke
    job = hook.get_job(job_id=self.airbyte_job_id)
          ^^^^^^^^^^^^^^^^^^^^^^^^^^^^^^^^^^^^^^^^
  File "/home/airflow/.local/lib/python3.11/site-packages/airflow/providers/airbyte/hooks/airbyte.py", line 104, in get_job
    return self.run(
           ^^^^^^^^^
  File "/home/airflow/.local/lib/python3.11/site-packages/airflow/providers/http/hooks/http.py", line 166, in run
    return self.run_and_check(session, prepped_request, extra_options)
           ^^^^^^^^^^^^^^^^^^^^^^^^^^^^^^^^^^^^^^^^^^^^^^^^^^^^^^^^^^^
  File "/home/airflow/.local/lib/python3.11/site-packages/airflow/providers/http/hooks/http.py", line 217, in run_and_check
    self.check_response(response)
  File "/home/airflow/.local/lib/python3.11/site-packages/airflow/providers/http/hooks/http.py", line 180, in check_response
    raise AirflowException(str(response.status_code) + ":" + response.reason)
airflow.exceptions.AirflowException: 502:Bad Gateway
[2023-12-12T01:33:16.096+0000] {taskinstance.py:1400} INFO - Marking task as FAILED. dag_id=airbyte_rtgs_data_processing_***_dag, task_id=airbyte_check_deposit_transactions, execution_date=20231212T012917, start_date=20231212T012938, end_date=20231212T013316
[2023-12-12T01:33:16.160+0000] {standard_task_runner.py:104} ERROR - Failed to execute job 72 for task airbyte_check_deposit_transactions (502:Bad Gateway; 424)
[2023-12-12T01:33:16.327+0000] {local_task_job_runner.py:228} INFO - Task exited with return code 1
[2023-12-12T01:33:19.220+0000] {taskinstance.py:2778} INFO - 0 downstream tasks scheduled from follow-on schedule check
