[2023-12-12T00:43:50.553+0000] {taskinstance.py:1159} INFO - Dependencies all met for dep_context=non-requeueable deps ti=<TaskInstance: airbyte_mambu_data_processing_airflow_dag.airbyte_check_deposit_transactions manual__2023-12-12T00:43:04.155864+00:00 [queued]>
[2023-12-12T00:43:50.558+0000] {taskinstance.py:1159} INFO - Dependencies all met for dep_context=requeueable deps ti=<TaskInstance: airbyte_mambu_data_processing_airflow_dag.airbyte_check_deposit_transactions manual__2023-12-12T00:43:04.155864+00:00 [queued]>
[2023-12-12T00:43:50.559+0000] {taskinstance.py:1361} INFO - Starting attempt 1 of 1
[2023-12-12T00:43:51.086+0000] {taskinstance.py:1382} INFO - Executing <Task(AirbyteJobSensor): airbyte_check_deposit_transactions> on 2023-12-12 00:43:04.155864+00:00
[2023-12-12T00:43:51.096+0000] {standard_task_runner.py:57} INFO - Started process 4348 to run task
[2023-12-12T00:43:51.099+0000] {standard_task_runner.py:84} INFO - Running: ['***', 'tasks', 'run', 'airbyte_mambu_data_processing_***_dag', 'airbyte_check_deposit_transactions', 'manual__2023-12-12T00:43:04.155864+00:00', '--job-id', '53', '--raw', '--subdir', 'DAGS_FOLDER/mambu_data_processing.py', '--cfg-path', '/tmp/tmprvr4wabr']
[2023-12-12T00:43:51.102+0000] {standard_task_runner.py:85} INFO - Job 53: Subtask airbyte_check_deposit_transactions
[2023-12-12T00:43:51.131+0000] {task_command.py:416} INFO - Running <TaskInstance: airbyte_mambu_data_processing_airflow_dag.airbyte_check_deposit_transactions manual__2023-12-12T00:43:04.155864+00:00 [running]> on host 012a6ed4c30b
[2023-12-12T00:43:51.179+0000] {taskinstance.py:1662} INFO - Exporting env vars: AIRFLOW_CTX_DAG_OWNER='***' AIRFLOW_CTX_DAG_ID='airbyte_mambu_data_processing_***_dag' AIRFLOW_CTX_TASK_ID='airbyte_check_deposit_transactions' AIRFLOW_CTX_EXECUTION_DATE='2023-12-12T00:43:04.155864+00:00' AIRFLOW_CTX_TRY_NUMBER='1' AIRFLOW_CTX_DAG_RUN_ID='manual__2023-12-12T00:43:04.155864+00:00'
[2023-12-12T00:43:51.187+0000] {base.py:73} INFO - Using connection ID '***-call-to-airbyte' for task execution.
[2023-12-12T00:43:51.246+0000] {airbyte.py:80} INFO - Waiting for job 13 to complete.
[2023-12-12T00:44:51.288+0000] {base.py:73} INFO - Using connection ID '***-call-to-airbyte' for task execution.
[2023-12-12T00:44:51.313+0000] {http.py:178} ERROR - HTTP error: Bad Gateway
[2023-12-12T00:44:51.314+0000] {http.py:179} ERROR - <!DOCTYPE html>
<html>
<head>
<title>Error</title>
<style>
html { color-scheme: light dark; }
body { width: 35em; margin: 0 auto;
font-family: Tahoma, Verdana, Arial, sans-serif; }
</style>
</head>
<body>
<h1>An error occurred.</h1>
<p>Sorry, the page you are looking for is currently unavailable.<br/>
Please try again later.</p>
<p>If you are the system administrator of this resource then you should check
the error log for details.</p>
<p><em>Faithfully yours, nginx.</em></p>
</body>
</html>

[2023-12-12T00:44:51.337+0000] {taskinstance.py:1937} ERROR - Task failed with exception
Traceback (most recent call last):
  File "/home/airflow/.local/lib/python3.11/site-packages/airflow/providers/http/hooks/http.py", line 176, in check_response
    response.raise_for_status()
  File "/home/airflow/.local/lib/python3.11/site-packages/requests/models.py", line 1021, in raise_for_status
    raise HTTPError(http_error_msg, response=self)
requests.exceptions.HTTPError: 502 Server Error: Bad Gateway for url: http://host.docker.internal:80/api/v1/jobs/get

During handling of the above exception, another exception occurred:

Traceback (most recent call last):
  File "/home/airflow/.local/lib/python3.11/site-packages/airflow/sensors/base.py", line 257, in execute
    raise e
  File "/home/airflow/.local/lib/python3.11/site-packages/airflow/sensors/base.py", line 239, in execute
    poke_return = self.poke(context)
                  ^^^^^^^^^^^^^^^^^^
  File "/home/airflow/.local/lib/python3.11/site-packages/airflow/providers/airbyte/sensors/airbyte.py", line 59, in poke
    job = hook.get_job(job_id=self.airbyte_job_id)
          ^^^^^^^^^^^^^^^^^^^^^^^^^^^^^^^^^^^^^^^^
  File "/home/airflow/.local/lib/python3.11/site-packages/airflow/providers/airbyte/hooks/airbyte.py", line 104, in get_job
    return self.run(
           ^^^^^^^^^
  File "/home/airflow/.local/lib/python3.11/site-packages/airflow/providers/http/hooks/http.py", line 166, in run
    return self.run_and_check(session, prepped_request, extra_options)
           ^^^^^^^^^^^^^^^^^^^^^^^^^^^^^^^^^^^^^^^^^^^^^^^^^^^^^^^^^^^
  File "/home/airflow/.local/lib/python3.11/site-packages/airflow/providers/http/hooks/http.py", line 217, in run_and_check
    self.check_response(response)
  File "/home/airflow/.local/lib/python3.11/site-packages/airflow/providers/http/hooks/http.py", line 180, in check_response
    raise AirflowException(str(response.status_code) + ":" + response.reason)
airflow.exceptions.AirflowException: 502:Bad Gateway
[2023-12-12T00:44:51.349+0000] {taskinstance.py:1400} INFO - Marking task as FAILED. dag_id=airbyte_mambu_data_processing_***_dag, task_id=airbyte_check_deposit_transactions, execution_date=20231212T004304, start_date=20231212T004350, end_date=20231212T004451
[2023-12-12T00:44:51.394+0000] {standard_task_runner.py:104} ERROR - Failed to execute job 53 for task airbyte_check_deposit_transactions (502:Bad Gateway; 4348)
[2023-12-12T00:44:51.450+0000] {local_task_job_runner.py:228} INFO - Task exited with return code 1
[2023-12-12T00:44:51.497+0000] {taskinstance.py:2778} INFO - 0 downstream tasks scheduled from follow-on schedule check
