[2023-11-26T19:36:20.480+0000] {taskinstance.py:1159} INFO - Dependencies all met for dep_context=non-requeueable deps ti=<TaskInstance: airbyte_example_airflow_dag.airbyte_trigger_sync scheduled__2023-11-25T00:00:00+00:00 [queued]>
[2023-11-26T19:36:20.489+0000] {taskinstance.py:1159} INFO - Dependencies all met for dep_context=requeueable deps ti=<TaskInstance: airbyte_example_airflow_dag.airbyte_trigger_sync scheduled__2023-11-25T00:00:00+00:00 [queued]>
[2023-11-26T19:36:20.489+0000] {taskinstance.py:1361} INFO - Starting attempt 1 of 1
[2023-11-26T19:36:20.535+0000] {taskinstance.py:1382} INFO - Executing <Task(AirbyteTriggerSyncOperator): airbyte_trigger_sync> on 2023-11-25 00:00:00+00:00
[2023-11-26T19:36:20.540+0000] {standard_task_runner.py:57} INFO - Started process 91 to run task
[2023-11-26T19:36:20.542+0000] {standard_task_runner.py:84} INFO - Running: ['***', 'tasks', 'run', 'airbyte_example_***_dag', 'airbyte_trigger_sync', 'scheduled__2023-11-25T00:00:00+00:00', '--job-id', '83', '--raw', '--subdir', 'DAGS_FOLDER/example.py', '--cfg-path', '/tmp/tmpii6uv7pc']
[2023-11-26T19:36:20.543+0000] {standard_task_runner.py:85} INFO - Job 83: Subtask airbyte_trigger_sync
[2023-11-26T19:36:20.658+0000] {task_command.py:416} INFO - Running <TaskInstance: airbyte_example_airflow_dag.airbyte_trigger_sync scheduled__2023-11-25T00:00:00+00:00 [running]> on host 471f0a6f2fee
[2023-11-26T19:36:21.579+0000] {taskinstance.py:1662} INFO - Exporting env vars: AIRFLOW_CTX_DAG_OWNER='***' AIRFLOW_CTX_DAG_ID='airbyte_example_***_dag' AIRFLOW_CTX_TASK_ID='airbyte_trigger_sync' AIRFLOW_CTX_EXECUTION_DATE='2023-11-25T00:00:00+00:00' AIRFLOW_CTX_TRY_NUMBER='1' AIRFLOW_CTX_DAG_RUN_ID='scheduled__2023-11-25T00:00:00+00:00'
[2023-11-26T19:36:21.817+0000] {base.py:73} INFO - Using connection ID '***-call-to-airbyte-example' for task execution.
[2023-11-26T19:36:22.147+0000] {http.py:178} ERROR - HTTP error: Bad Gateway
[2023-11-26T19:36:22.148+0000] {http.py:179} ERROR - <!DOCTYPE html>
<html>
<head>
<title>Error</title>
<style>
html { color-scheme: light dark; }
body { width: 35em; margin: 0 auto;
font-family: Tahoma, Verdana, Arial, sans-serif; }
</style>
</head>
<body>
<h1>An error occurred.</h1>
<p>Sorry, the page you are looking for is currently unavailable.<br/>
Please try again later.</p>
<p>If you are the system administrator of this resource then you should check
the error log for details.</p>
<p><em>Faithfully yours, nginx.</em></p>
</body>
</html>

[2023-11-26T19:36:22.155+0000] {taskinstance.py:1937} ERROR - Task failed with exception
Traceback (most recent call last):
  File "/home/airflow/.local/lib/python3.8/site-packages/airflow/providers/http/hooks/http.py", line 176, in check_response
    response.raise_for_status()
  File "/home/airflow/.local/lib/python3.8/site-packages/requests/models.py", line 1021, in raise_for_status
    raise HTTPError(http_error_msg, response=self)
requests.exceptions.HTTPError: 502 Server Error: Bad Gateway for url: http://host.docker.internal:8000/api/v1/connections/sync

During handling of the above exception, another exception occurred:

Traceback (most recent call last):
  File "/home/airflow/.local/lib/python3.8/site-packages/airflow/providers/airbyte/operators/airbyte.py", line 73, in execute
    job_object = self.hook.submit_sync_connection(connection_id=self.connection_id)
  File "/home/airflow/.local/lib/python3.8/site-packages/airflow/providers/airbyte/hooks/airbyte.py", line 92, in submit_sync_connection
    return self.run(
  File "/home/airflow/.local/lib/python3.8/site-packages/airflow/providers/http/hooks/http.py", line 166, in run
    return self.run_and_check(session, prepped_request, extra_options)
  File "/home/airflow/.local/lib/python3.8/site-packages/airflow/providers/http/hooks/http.py", line 217, in run_and_check
    self.check_response(response)
  File "/home/airflow/.local/lib/python3.8/site-packages/airflow/providers/http/hooks/http.py", line 180, in check_response
    raise AirflowException(str(response.status_code) + ":" + response.reason)
airflow.exceptions.AirflowException: 502:Bad Gateway
[2023-11-26T19:36:22.387+0000] {taskinstance.py:1400} INFO - Marking task as FAILED. dag_id=airbyte_example_***_dag, task_id=airbyte_trigger_sync, execution_date=20231125T000000, start_date=20231126T193620, end_date=20231126T193622
[2023-11-26T19:36:22.628+0000] {standard_task_runner.py:104} ERROR - Failed to execute job 83 for task airbyte_trigger_sync (502:Bad Gateway; 91)
[2023-11-26T19:36:22.641+0000] {local_task_job_runner.py:228} INFO - Task exited with return code 1
[2023-11-26T19:36:22.667+0000] {taskinstance.py:2778} INFO - 0 downstream tasks scheduled from follow-on schedule check
