[2023-12-12T02:00:49.932+0000] {taskinstance.py:1159} INFO - Dependencies all met for dep_context=non-requeueable deps ti=<TaskInstance: airbyte_rtgs_data_processing_airflow_dag.airbyte_trigger_sync_rtgs_deposit_transactions manual__2023-12-12T02:00:31.459240+00:00 [queued]>
[2023-12-12T02:00:49.943+0000] {taskinstance.py:1159} INFO - Dependencies all met for dep_context=requeueable deps ti=<TaskInstance: airbyte_rtgs_data_processing_airflow_dag.airbyte_trigger_sync_rtgs_deposit_transactions manual__2023-12-12T02:00:31.459240+00:00 [queued]>
[2023-12-12T02:00:49.944+0000] {taskinstance.py:1361} INFO - Starting attempt 1 of 1
[2023-12-12T02:00:49.957+0000] {taskinstance.py:1382} INFO - Executing <Task(AirbyteTriggerSyncOperator): airbyte_trigger_sync_rtgs_deposit_transactions> on 2023-12-12 02:00:31.459240+00:00
[2023-12-12T02:00:49.964+0000] {standard_task_runner.py:57} INFO - Started process 129 to run task
[2023-12-12T02:00:49.968+0000] {standard_task_runner.py:84} INFO - Running: ['***', 'tasks', 'run', 'airbyte_rtgs_data_processing_***_dag', 'airbyte_trigger_sync_rtgs_deposit_transactions', 'manual__2023-12-12T02:00:31.459240+00:00', '--job-id', '93', '--raw', '--subdir', 'DAGS_FOLDER/rtgs_data_processing.py', '--cfg-path', '/tmp/tmpb6yz53sx']
[2023-12-12T02:00:49.971+0000] {standard_task_runner.py:85} INFO - Job 93: Subtask airbyte_trigger_sync_rtgs_deposit_transactions
[2023-12-12T02:00:50.057+0000] {task_command.py:416} INFO - Running <TaskInstance: airbyte_rtgs_data_processing_airflow_dag.airbyte_trigger_sync_rtgs_deposit_transactions manual__2023-12-12T02:00:31.459240+00:00 [running]> on host 86ddea81acd7
[2023-12-12T02:00:50.615+0000] {taskinstance.py:1662} INFO - Exporting env vars: AIRFLOW_CTX_DAG_OWNER='***' AIRFLOW_CTX_DAG_ID='airbyte_rtgs_data_processing_***_dag' AIRFLOW_CTX_TASK_ID='airbyte_trigger_sync_rtgs_deposit_transactions' AIRFLOW_CTX_EXECUTION_DATE='2023-12-12T02:00:31.459240+00:00' AIRFLOW_CTX_TRY_NUMBER='1' AIRFLOW_CTX_DAG_RUN_ID='manual__2023-12-12T02:00:31.459240+00:00'
[2023-12-12T02:00:50.627+0000] {base.py:73} INFO - Using connection ID '***-call-to-airbyte' for task execution.
[2023-12-12T02:00:50.839+0000] {http.py:178} ERROR - HTTP error: Conflict
[2023-12-12T02:00:50.841+0000] {http.py:179} ERROR - {"message":"A sync is already running for: 2fe027a7-c83b-4b09-ad8d-b2d109b78808","exceptionClassName":"io.airbyte.commons.server.errors.ValueConflictKnownException","exceptionStack":["io.airbyte.commons.server.errors.ValueConflictKnownException: A sync is already running for: 2fe027a7-c83b-4b09-ad8d-b2d109b78808","\tat io.airbyte.commons.server.handlers.SchedulerHandler.readJobFromResult(SchedulerHandler.java:827)","\tat io.airbyte.commons.server.handlers.SchedulerHandler.submitManualSyncToWorker(SchedulerHandler.java:797)","\tat io.airbyte.commons.server.handlers.SchedulerHandler.syncConnection(SchedulerHandler.java:586)","\tat io.airbyte.server.apis.ConnectionApiController.lambda$syncConnection$11(ConnectionApiController.java:220)","\tat io.airbyte.server.apis.ApiHelper.execute(ApiHelper.java:27)","\tat io.airbyte.server.apis.ConnectionApiController.syncConnection(ConnectionApiController.java:220)","\tat io.airbyte.server.apis.$ConnectionApiController$Definition$Exec.dispatch(Unknown Source)","\tat io.micronaut.context.AbstractExecutableMethodsDefinition$DispatchedExecutableMethod.invoke(AbstractExecutableMethodsDefinition.java:371)","\tat io.micronaut.context.DefaultBeanContext$4.invoke(DefaultBeanContext.java:594)","\tat io.micronaut.web.router.AbstractRouteMatch.execute(AbstractRouteMatch.java:303)","\tat io.micronaut.web.router.RouteMatch.execute(RouteMatch.java:111)","\tat io.micronaut.http.context.ServerRequestContext.with(ServerRequestContext.java:103)","\tat io.micronaut.http.server.RouteExecutor.lambda$executeRoute$14(RouteExecutor.java:659)","\tat reactor.core.publisher.FluxDeferContextual.subscribe(FluxDeferContextual.java:49)","\tat reactor.core.publisher.InternalFluxOperator.subscribe(InternalFluxOperator.java:62)","\tat reactor.core.publisher.FluxSubscribeOn$SubscribeOnSubscriber.run(FluxSubscribeOn.java:194)","\tat io.micronaut.reactive.reactor.instrument.ReactorInstrumentation.lambda$init$0(ReactorInstrumentation.java:62)","\tat reactor.core.scheduler.WorkerTask.call(WorkerTask.java:84)","\tat reactor.core.scheduler.WorkerTask.call(WorkerTask.java:37)","\tat io.micronaut.scheduling.instrument.InvocationInstrumenterWrappedCallable.call(InvocationInstrumenterWrappedCallable.java:53)","\tat java.base/java.util.concurrent.FutureTask.run(FutureTask.java:317)","\tat java.base/java.util.concurrent.ThreadPoolExecutor.runWorker(ThreadPoolExecutor.java:1144)","\tat java.base/java.util.concurrent.ThreadPoolExecutor$Worker.run(ThreadPoolExecutor.java:642)","\tat java.base/java.lang.Thread.run(Thread.java:1589)"]}
[2023-12-12T02:00:50.858+0000] {taskinstance.py:1937} ERROR - Task failed with exception
Traceback (most recent call last):
  File "/home/airflow/.local/lib/python3.11/site-packages/airflow/providers/http/hooks/http.py", line 176, in check_response
    response.raise_for_status()
  File "/home/airflow/.local/lib/python3.11/site-packages/requests/models.py", line 1021, in raise_for_status
    raise HTTPError(http_error_msg, response=self)
requests.exceptions.HTTPError: 409 Client Error: Conflict for url: http://host.docker.internal:80/api/v1/connections/sync

During handling of the above exception, another exception occurred:

Traceback (most recent call last):
  File "/home/airflow/.local/lib/python3.11/site-packages/airflow/providers/airbyte/operators/airbyte.py", line 73, in execute
    job_object = self.hook.submit_sync_connection(connection_id=self.connection_id)
                 ^^^^^^^^^^^^^^^^^^^^^^^^^^^^^^^^^^^^^^^^^^^^^^^^^^^^^^^^^^^^^^^^^^
  File "/home/airflow/.local/lib/python3.11/site-packages/airflow/providers/airbyte/hooks/airbyte.py", line 92, in submit_sync_connection
    return self.run(
           ^^^^^^^^^
  File "/home/airflow/.local/lib/python3.11/site-packages/airflow/providers/http/hooks/http.py", line 166, in run
    return self.run_and_check(session, prepped_request, extra_options)
           ^^^^^^^^^^^^^^^^^^^^^^^^^^^^^^^^^^^^^^^^^^^^^^^^^^^^^^^^^^^
  File "/home/airflow/.local/lib/python3.11/site-packages/airflow/providers/http/hooks/http.py", line 217, in run_and_check
    self.check_response(response)
  File "/home/airflow/.local/lib/python3.11/site-packages/airflow/providers/http/hooks/http.py", line 180, in check_response
    raise AirflowException(str(response.status_code) + ":" + response.reason)
airflow.exceptions.AirflowException: 409:Conflict
[2023-12-12T02:00:50.871+0000] {taskinstance.py:1400} INFO - Marking task as FAILED. dag_id=airbyte_rtgs_data_processing_***_dag, task_id=airbyte_trigger_sync_rtgs_deposit_transactions, execution_date=20231212T020031, start_date=20231212T020049, end_date=20231212T020050
[2023-12-12T02:00:50.890+0000] {standard_task_runner.py:104} ERROR - Failed to execute job 93 for task airbyte_trigger_sync_rtgs_deposit_transactions (409:Conflict; 129)
[2023-12-12T02:00:50.914+0000] {local_task_job_runner.py:228} INFO - Task exited with return code 1
[2023-12-12T02:00:50.950+0000] {taskinstance.py:2778} INFO - 0 downstream tasks scheduled from follow-on schedule check
